Workbook

Sheet Расшифровка
C1: NVM CONTENT | U1: NVM LONG TIME DRIFT
C2: SN | F2: =CONCATENATE(RIGHT(com!A1313,1),RIGHT(com!A1314,1),RIGHT(com!A1315,1),RIGHT(com!A1316,1),RIGHT(com!A1317,1),RIGHT(com!A1318,1),RIGHT(com!A1319,1)) | I2: PC | L2: =(HEX2DEC(RIGHT(com!A1337,2)&LEFT(com!A1337,2))/1024)/0.0145 | M2: hPA | P2: delta | Q2: =1020-L2+L4 | U2: Использовать delta | W2: Да | X2: иначе | Y2: -30 | Z2: =IF(W2="Да",Q2,Y2) | AA2: hPA
C3: HW PN | F3: =CONCATENATE(RIGHT(com!A1320,1),RIGHT(com!A1321,1),RIGHT(com!A1322,1),RIGHT(com!A1323,1),"-",RIGHT(com!A1325,1),RIGHT(com!A1326,1),RIGHT(com!A1327,1),RIGHT(com!A1328,1),RIGHT(com!A1329,1),"-",RIGHT(com!A1331,1),RIGHT(com!A1332,1)) | I3: ALT_CAB_RATO | L3: =(HEX2DEC(RIGHT(com!A1338,2)&LEFT(com!A1338,2))/4) | M3: SLFPM | P3: Контроль | Q3: =IF(OR(ABS(L6)>12,ABS(Q2) >12),"ЗАМЕНИТЕ ДАТЧИК","ДАТЧИК ИСПРАВЕН") | U3: PC_OFFSET_NVM | W3: =IF(ROUND($Z$2*0.0145*2048,0)>=0,TEXT(DEC2HEX(ROUND($Z$2*0.0145*2048,0),4),"0000"),DEC2HEX(ROUND($Z$2*0.0145*2048,0)+65535)) | X3: ="N00A1"&RIGHT(W3,2)&LEFT(W3,2)
C4: SW PN | F4: =VLOOKUP(com!A1335,ASCII!C:E,3,0)&VLOOKUP(com!A1336,ASCII!C:E,3,0) | I4: PC_OFFSET_NVM | L4: =IF(HEX2DEC(RIGHT(com!A1339,2)&LEFT(com!A1339,2))<=4095,(HEX2DEC(RIGHT(com!A1339,2)&LEFT(com!A1339,2))/2048)/0.0145,((65535-HEX2DEC(RIGHT(com!A1339,2)&LEFT(com!A1339,2)))/2048)/-0.0145) | M4: hPA | U4: PC_OFFSET_NVM_CHECKSUM | W4: =IF(ROUND($Z$2*0.0145*2048,0)>=0,DEC2HEX(ROUND($Z$2*-0.0145*2048,0)+65535),TEXT(DEC2HEX(ROUND($Z$2*-0.0145*2048,0),4),"0000")) | X4: ="N02A1"&RIGHT(W4,2)&LEFT(W4,2)
C5: SW VERSION | F5: =CONCATENATE(RIGHT(com!A1334,1),RIGHT(com!A1333,1)) | I5: PC_OFFSET_NVM_CHECKSUM | L5: =IF(HEX2DEC(RIGHT(com!A1340,2)&LEFT(com!A1340,2))<=4095,(HEX2DEC(RIGHT(com!A1340,2)&LEFT(com!A1340,2))/2048)/0.0145,((65535-HEX2DEC(RIGHT(com!A1340,2)&LEFT(com!A1340,2)))/2048)/-0.0145) | M5: hPA | U5: PC_CHECK_OFFST | W5: =IF(ROUND($Z$2*0.0145*2048,0)>=0,TEXT(DEC2HEX(ROUND($Z$2*0.0145*2048,0)),"0000"),DEC2HEX(ROUND($Z$2*0.0145*2048,0)+65535)) | X5: ="N04A1"&RIGHT(W5,2)&LEFT(W5,2)
I6: PC_CHECK_OFFST | L6: =IF(HEX2DEC(RIGHT(com!A1341,2)&LEFT(com!A1341,2))<=32768,(HEX2DEC(RIGHT(com!A1341,2)&LEFT(com!A1341,2))/2048)/0.0145,((65535-HEX2DEC(RIGHT(com!A1341,2)&LEFT(com!A1341,2)))/2048)/-0.0145) | M6: hPA | U6: DRIFT_COMP_CNT | W6: 0 | X6: N06A10000
I7: DRIFT_COMP_CNT | L7: =HEX2DEC(RIGHT(com!A1343,2)&LEFT(com!A1343,2)&RIGHT(com!A1342,2)&LEFT(com!A1342,2)) | M7: counter | X7: N08A10000 | AO7: Выбор
I8: PC_OFFSET_FAIL_CNT | L8: =(HEX2DEC(com!A1344)) | M8: counter | AP8: Да
C9: NVM BITE CONTENT | AP9: Нет
F10: =Исходник!E4 | G10: =Исходник!F4 | H10: =Исходник!G4 | I10: =Исходник!H4 | J10: =Исходник!I4 | K10: =Исходник!J4 | L10: =Исходник!K4 | M10: =Исходник!L4 | ... AK10: =Исходник!AJ4
C11: =Исходник!B5 | F11: =HEX2DEC(RIGHT(Исходник!E5,2)) | G11: =HEX2DEC(RIGHT(Исходник!F5,2)) | H11: =HEX2DEC(RIGHT(Исходник!G5,2)) | I11: =HEX2DEC(RIGHT(Исходник!H5,2)) | J11: =HEX2DEC(RIGHT(Исходник!I5,2)) | K11: =HEX2DEC(RIGHT(Исходник!J5,2)) | L11: =HEX2DEC(RIGHT(Исходник!K5,2)) | M11: =HEX2DEC(RIGHT(Исходник!L5,2)) | ... AK11: =HEX2DEC(RIGHT(Исходник!AJ5,2)) | AO11: FLIGHT MODE
C12: =Исходник!B6 | F12: =HEX2DEC(RIGHT(Исходник!E6,2)) | G12: =HEX2DEC(RIGHT(Исходник!F6,2)) | H12: =HEX2DEC(RIGHT(Исходник!G6,2)) | I12: =HEX2DEC(RIGHT(Исходник!H6,2)) | J12: =HEX2DEC(RIGHT(Исходник!I6,2)) | K12: =HEX2DEC(RIGHT(Исходник!J6,2)) | L12: =HEX2DEC(RIGHT(Исходник!K6,2)) | M12: =HEX2DEC(RIGHT(Исходник!L6,2)) | ... AK12: =HEX2DEC(RIGHT(Исходник!AJ6,2)) | AO12: 0 | AP12: GROUND
C13: =Исходник!B7 | F13: =HEX2DEC(RIGHT(Исходник!E7,2)) | G13: =HEX2DEC(RIGHT(Исходник!F7,2)) | H13: =HEX2DEC(RIGHT(Исходник!G7,2)) | I13: =HEX2DEC(RIGHT(Исходник!H7,2)) | J13: =HEX2DEC(RIGHT(Исходник!I7,2)) | K13: =HEX2DEC(RIGHT(Исходник!J7,2)) | L13: =HEX2DEC(RIGHT(Исходник!K7,2)) | M13: =HEX2DEC(RIGHT(Исходник!L7,2)) | ... AK13: =HEX2DEC(RIGHT(Исходник!AJ7,2)) | AO13: 1 | AP13: TAKE OFF
C14: =Исходник!B8 | F14: =VLOOKUP(HEX2DEC(RIGHT(Исходник!E8,2)),$AO$12:$AP$20,2,FALSE) | G14: =VLOOKUP(HEX2DEC(RIGHT(Исходник!F8,2)),$AO$12:$AP$20,2,FALSE) | H14: =VLOOKUP(HEX2DEC(RIGHT(Исходник!G8,2)),$AO$12:$AP$20,2,FALSE) | I14: =VLOOKUP(HEX2DEC(RIGHT(Исходник!H8,2)),$AO$12:$AP$20,2,FALSE) | J14: =VLOOKUP(HEX2DEC(RIGHT(Исходник!I8,2)),$AO$12:$AP$20,2,FALSE) | K14: =VLOOKUP(HEX2DEC(RIGHT(Исходник!J8,2)),$AO$12:$AP$20,2,FALSE) | L14: =VLOOKUP(HEX2DEC(RIGHT(Исходник!K8,2)),$AO$12:$AP$20,2,FALSE) | M14: =VLOOKUP(HEX2DEC(RIGHT(Исходник!L8,2)),$AO$12:$AP$20,2,FALSE) | ... AK14: =VLOOKUP(HEX2DEC(RIGHT(Исходник!AJ8,2)),$AO$12:$AP$20,2,FALSE) | AO14: 2 | AP14: CLIMB INT
C15: =Исходник!B9 | F15: =HEX2DEC(RIGHT(Исходник!E9,2)) | G15: =HEX2DEC(RIGHT(Исходник!F9,2)) | H15: =HEX2DEC(RIGHT(Исходник!G9,2)) | I15: =HEX2DEC(RIGHT(Исходник!H9,2)) | J15: =HEX2DEC(RIGHT(Исходник!I9,2)) | K15: =HEX2DEC(RIGHT(Исходник!J9,2)) | L15: =HEX2DEC(RIGHT(Исходник!K9,2)) | M15: =HEX2DEC(RIGHT(Исходник!L9,2)) | ... AK15: =HEX2DEC(RIGHT(Исходник!AJ9,2)) | AO15: 3 | AP15: CLIMB EXT
C16: =Исходник!B10 | F16: =VLOOKUP(HEX2DEC(RIGHT(Исходник!E10,2)),$AO$24:$AP$35,2,FALSE) | G16: =VLOOKUP(HEX2DEC(RIGHT(Исходник!F10,2)),$AO$24:$AP$35,2,FALSE) | H16: =VLOOKUP(HEX2DEC(RIGHT(Исходник!G10,2)),$AO$24:$AP$35,2,FALSE) | I16: =VLOOKUP(HEX2DEC(RIGHT(Исходник!H10,2)),$AO$24:$AP$35,2,FALSE) | J16: =VLOOKUP(HEX2DEC(RIGHT(Исходник!I10,2)),$AO$24:$AP$35,2,FALSE) | K16: =VLOOKUP(HEX2DEC(RIGHT(Исходник!J10,2)),$AO$24:$AP$35,2,FALSE) | L16: =VLOOKUP(HEX2DEC(RIGHT(Исходник!K10,2)),$AO$24:$AP$35,2,FALSE) | M16: =VLOOKUP(HEX2DEC(RIGHT(Исходник!L10,2)),$AO$24:$AP$35,2,FALSE) | ... AK16: =VLOOKUP(HEX2DEC(RIGHT(Исходник!AJ10,2)),$AO$24:$AP$35,2,FALSE) | AO16: 4 | AP16: ABORT
C17: =Исходник!B11 | F17: =IFERROR(CHAR(HEX2DEC(Исходник!E11)),"") | G17: =IFERROR(CHAR(HEX2DEC(Исходник!F11)),"") | H17: =IFERROR(CHAR(HEX2DEC(Исходник!G11)),"") | I17: =IFERROR(CHAR(HEX2DEC(Исходник!H11)),"") | J17: =IFERROR(CHAR(HEX2DEC(Исходник!I11)),"") | K17: =IFERROR(CHAR(HEX2DEC(Исходник!J11)),"") | L17: =IFERROR(CHAR(HEX2DEC(Исходник!K11)),"") | M17: =IFERROR(CHAR(HEX2DEC(Исходник!L11)),"") | ... AK17: =IFERROR(CHAR(HEX2DEC(Исходник!AJ11)),"") | AO17: 5 | AP17: CRUISE
C18: =Исходник!B12 | F18: =IFERROR(CHAR(HEX2DEC(Исходник!E12)),"") | G18: =IFERROR(CHAR(HEX2DEC(Исходник!F12)),"") | H18: =IFERROR(CHAR(HEX2DEC(Исходник!G12)),"") | I18: =IFERROR(CHAR(HEX2DEC(Исходник!H12)),"") | J18: =IFERROR(CHAR(HEX2DEC(Исходник!I12)),"") | K18: =IFERROR(CHAR(HEX2DEC(Исходник!J12)),"") | L18: =IFERROR(CHAR(HEX2DEC(Исходник!K12)),"") | M18: =IFERROR(CHAR(HEX2DEC(Исходник!L12)),"") | ... AK18: =IFERROR(CHAR(HEX2DEC(Исходник!AJ12)),"") | AO18: 6 | AP18: DESCENT INT
C19: =Исходник!B13 | F19: =IFERROR(CHAR(HEX2DEC(Исходник!E13)),"") | G19: =IFERROR(CHAR(HEX2DEC(Исходник!F13)),"") | H19: =IFERROR(CHAR(HEX2DEC(Исходник!G13)),"") | I19: =IFERROR(CHAR(HEX2DEC(Исходник!H13)),"") | J19: =IFERROR(CHAR(HEX2DEC(Исходник!I13)),"") | K19: =IFERROR(CHAR(HEX2DEC(Исходник!J13)),"") | L19: =IFERROR(CHAR(HEX2DEC(Исходник!K13)),"") | M19: =IFERROR(CHAR(HEX2DEC(Исходник!L13)),"") | ... AK19: =IFERROR(CHAR(HEX2DEC(Исходник!AJ13)),"") | AO19: 7 | AP19: DESCENT EXT
C20: =Исходник!B14 | F20: =IFERROR(CHAR(HEX2DEC(Исходник!E14)),"") | G20: =IFERROR(CHAR(HEX2DEC(Исходник!F14)),"") | H20: =IFERROR(CHAR(HEX2DEC(Исходник!G14)),"") | I20: =IFERROR(CHAR(HEX2DEC(Исходник!H14)),"") | J20: =IFERROR(CHAR(HEX2DEC(Исходник!I14)),"") | K20: =IFERROR(CHAR(HEX2DEC(Исходник!J14)),"") | L20: =IFERROR(CHAR(HEX2DEC(Исходник!K14)),"") | M20: =IFERROR(CHAR(HEX2DEC(Исходник!L14)),"") | ... AK20: =IFERROR(CHAR(HEX2DEC(Исходник!AJ14)),"") | AO20: 256 | AP20: NOT INIT
C21: =Исходник!B15 | F21: =IFERROR(CHAR(HEX2DEC(Исходник!E15)),"") | G21: =IFERROR(CHAR(HEX2DEC(Исходник!F15)),"") | H21: =IFERROR(CHAR(HEX2DEC(Исходник!G15)),"") | I21: =IFERROR(CHAR(HEX2DEC(Исходник!H15)),"") | J21: =IFERROR(CHAR(HEX2DEC(Исходник!I15)),"") | K21: =IFERROR(CHAR(HEX2DEC(Исходник!J15)),"") | L21: =IFERROR(CHAR(HEX2DEC(Исходник!K15)),"") | M21: =IFERROR(CHAR(HEX2DEC(Исходник!L15)),"") | ... AK21: =IFERROR(CHAR(HEX2DEC(Исходник!AJ15)),"")
C22: =Исходник!B16 | F22: =IFERROR(CHAR(HEX2DEC(Исходник!E16)),"") | G22: =IFERROR(CHAR(HEX2DEC(Исходник!F16)),"") | H22: =IFERROR(CHAR(HEX2DEC(Исходник!G16)),"") | I22: =IFERROR(CHAR(HEX2DEC(Исходник!H16)),"") | J22: =IFERROR(CHAR(HEX2DEC(Исходник!I16)),"") | K22: =IFERROR(CHAR(HEX2DEC(Исходник!J16)),"") | L22: =IFERROR(CHAR(HEX2DEC(Исходник!K16)),"") | M22: =IFERROR(CHAR(HEX2DEC(Исходник!L16)),"") | ... AK22: =IFERROR(CHAR(HEX2DEC(Исходник!AJ16)),"")
C23: =Исходник!B17 | F23: =IFERROR(CHAR(HEX2DEC(Исходник!E17)),"") | G23: =IFERROR(CHAR(HEX2DEC(Исходник!F17)),"") | H23: =IFERROR(CHAR(HEX2DEC(Исходник!G17)),"") | I23: =IFERROR(CHAR(HEX2DEC(Исходник!H17)),"") | J23: =IFERROR(CHAR(HEX2DEC(Исходник!I17)),"") | K23: =IFERROR(CHAR(HEX2DEC(Исходник!J17)),"") | L23: =IFERROR(CHAR(HEX2DEC(Исходник!K17)),"") | M23: =IFERROR(CHAR(HEX2DEC(Исходник!L17)),"") | ... AK23: =IFERROR(CHAR(HEX2DEC(Исходник!AJ17)),"") | AO23: FLIGHT PHASE
C24: =Исходник!B18 | F24: =IFERROR(CHAR(HEX2DEC(Исходник!E18)),"") | G24: =IFERROR(CHAR(HEX2DEC(Исходник!F18)),"") | H24: =IFERROR(CHAR(HEX2DEC(Исходник!G18)),"") | I24: =IFERROR(CHAR(HEX2DEC(Исходник!H18)),"") | J24: =IFERROR(CHAR(HEX2DEC(Исходник!I18)),"") | K24: =IFERROR(CHAR(HEX2DEC(Исходник!J18)),"") | L24: =IFERROR(CHAR(HEX2DEC(Исходник!K18)),"") | M24: =IFERROR(CHAR(HEX2DEC(Исходник!L18)),"") | ... AK24: =IFERROR(CHAR(HEX2DEC(Исходник!AJ18)),"") | AO24: 0
C25: =Исходник!B19 | F25: =IFERROR(CHAR(HEX2DEC(Исходник!E19)),"") | G25: =IFERROR(CHAR(HEX2DEC(Исходник!F19)),"") | H25: =IFERROR(CHAR(HEX2DEC(Исходник!G19)),"") | I25: =IFERROR(CHAR(HEX2DEC(Исходник!H19)),"") | J25: =IFERROR(CHAR(HEX2DEC(Исходник!I19)),"") | K25: =IFERROR(CHAR(HEX2DEC(Исходник!J19)),"") | L25: =IFERROR(CHAR(HEX2DEC(Исходник!K19)),"") | M25: =IFERROR(CHAR(HEX2DEC(Исходник!L19)),"") | ... AK25: =IFERROR(CHAR(HEX2DEC(Исходник!AJ19)),"") | AO25: 1 | AP25: POWER UP
C26: =Исходник!B20 | F26: =IFERROR(CHAR(HEX2DEC(Исходник!E20)),"") | G26: =IFERROR(CHAR(HEX2DEC(Исходник!F20)),"") | H26: =IFERROR(CHAR(HEX2DEC(Исходник!G20)),"") | I26: =IFERROR(CHAR(HEX2DEC(Исходник!H20)),"") | J26: =IFERROR(CHAR(HEX2DEC(Исходник!I20)),"") | K26: =IFERROR(CHAR(HEX2DEC(Исходник!J20)),"") | L26: =IFERROR(CHAR(HEX2DEC(Исходник!K20)),"") | M26: =IFERROR(CHAR(HEX2DEC(Исходник!L20)),"") | ... AK26: =IFERROR(CHAR(HEX2DEC(Исходник!AJ20)),"") | AO26: 2 | AP26: 1ST ENG START
C27: =Исходник!B21 | F27: =IFERROR(CHAR(HEX2DEC(Исходник!E21)),"") | G27: =IFERROR(CHAR(HEX2DEC(Исходник!F21)),"") | H27: =IFERROR(CHAR(HEX2DEC(Исходник!G21)),"") | I27: =IFERROR(CHAR(HEX2DEC(Исходник!H21)),"") | J27: =IFERROR(CHAR(HEX2DEC(Исходник!I21)),"") | K27: =IFERROR(CHAR(HEX2DEC(Исходник!J21)),"") | L27: =IFERROR(CHAR(HEX2DEC(Исходник!K21)),"") | M27: =IFERROR(CHAR(HEX2DEC(Исходник!L21)),"") | ... AK27: =IFERROR(CHAR(HEX2DEC(Исходник!AJ21)),"") | AO27: 3 | AP27: 1ST ENG TAKEOFF POWER
C28: =Исходник!B22 | F28: =IFERROR(CHAR(HEX2DEC(Исходник!E22)),"") | G28: =IFERROR(CHAR(HEX2DEC(Исходник!F22)),"") | H28: =IFERROR(CHAR(HEX2DEC(Исходник!G22)),"") | I28: =IFERROR(CHAR(HEX2DEC(Исходник!H22)),"") | J28: =IFERROR(CHAR(HEX2DEC(Исходник!I22)),"") | K28: =IFERROR(CHAR(HEX2DEC(Исходник!J22)),"") | L28: =IFERROR(CHAR(HEX2DEC(Исходник!K22)),"") | M28: =IFERROR(CHAR(HEX2DEC(Исходник!L22)),"") | ... AK28: =IFERROR(CHAR(HEX2DEC(Исходник!AJ22)),"") | AO28: 4 | AP28: OVER KNOTS LIM
C29: =Исходник!B23 | F29: =IFERROR(CHAR(HEX2DEC(Исходник!E23)),"") | G29: =IFERROR(CHAR(HEX2DEC(Исходник!F23)),"") | H29: =IFERROR(CHAR(HEX2DEC(Исходник!G23)),"") | I29: =IFERROR(CHAR(HEX2DEC(Исходник!H23)),"") | J29: =IFERROR(CHAR(HEX2DEC(Исходник!I23)),"") | K29: =IFERROR(CHAR(HEX2DEC(Исходник!J23)),"") | L29: =IFERROR(CHAR(HEX2DEC(Исходник!K23)),"") | M29: =IFERROR(CHAR(HEX2DEC(Исходник!L23)),"") | ... AK29: =IFERROR(CHAR(HEX2DEC(Исходник!AJ23)),"") | AO29: 5 | AP29: LIFT OFF
C30: =Исходник!B24 | F30: =IFERROR(CHAR(HEX2DEC(Исходник!E24)),"") | G30: =IFERROR(CHAR(HEX2DEC(Исходник!F24)),"") | H30: =IFERROR(CHAR(HEX2DEC(Исходник!G24)),"") | I30: =IFERROR(CHAR(HEX2DEC(Исходник!H24)),"") | J30: =IFERROR(CHAR(HEX2DEC(Исходник!I24)),"") | K30: =IFERROR(CHAR(HEX2DEC(Исходник!J24)),"") | L30: =IFERROR(CHAR(HEX2DEC(Исходник!K24)),"") | M30: =IFERROR(CHAR(HEX2DEC(Исходник!L24)),"") | ... AK30: =IFERROR(CHAR(HEX2DEC(Исходник!AJ24)),"") | AO30: 6 | AP30: CLIMB FEET
C31: =Исходник!B25 | F31: =IFERROR(CHAR(HEX2DEC(Исходник!E25)),"") | G31: =IFERROR(CHAR(HEX2DEC(Исходник!F25)),"") | H31: =IFERROR(CHAR(HEX2DEC(Исходник!G25)),"") | I31: =IFERROR(CHAR(HEX2DEC(Исходник!H25)),"") | J31: =IFERROR(CHAR(HEX2DEC(Исходник!I25)),"") | K31: =IFERROR(CHAR(HEX2DEC(Исходник!J25)),"") | L31: =IFERROR(CHAR(HEX2DEC(Исходник!K25)),"") | M31: =IFERROR(CHAR(HEX2DEC(Исходник!L25)),"") | ... AK31: =IFERROR(CHAR(HEX2DEC(Исходник!AJ25)),"") | AO31: 7 | AP31: DESCENT FEET
C32: =Исходник!B26 | F32: =RIGHT(Исходник!E26,2) | G32: =RIGHT(Исходник!F26,2) | H32: =RIGHT(Исходник!G26,2) | I32: =RIGHT(Исходник!H26,2) | J32: =RIGHT(Исходник!I26,2) | K32: =RIGHT(Исходник!J26,2) | L32: =RIGHT(Исходник!K26,2) | M32: =RIGHT(Исходник!L26,2) | ... AK32: =RIGHT(Исходник!AJ26,2) | AO32: 8 | AP32: TOUCH DOWN
C33: =Исходник!B27 | F33: =VALUE(RIGHT(Исходник!E27))*10 | G33: =VALUE(RIGHT(Исходник!F27))*10 | H33: =VALUE(RIGHT(Исходник!G27))*10 | I33: =VALUE(RIGHT(Исходник!H27))*10 | J33: =VALUE(RIGHT(Исходник!I27))*10 | K33: =VALUE(RIGHT(Исходник!J27))*10 | L33: =VALUE(RIGHT(Исходник!K27))*10 | M33: =VALUE(RIGHT(Исходник!L27))*10 | ... AK33: =VALUE(RIGHT(Исходник!AJ27))*10 | AO33: 9 | AP33: UNDER KNOTS
C34: =Исходник!B28 | F34: =VALUE(RIGHT(Исходник!E28,2))/10 | G34: =VALUE(RIGHT(Исходник!F28,2))/10 | H34: =VALUE(RIGHT(Исходник!G28,2))/10 | I34: =VALUE(RIGHT(Исходник!H28,2))/10 | J34: =VALUE(RIGHT(Исходник!I28,2))/10 | K34: =VALUE(RIGHT(Исходник!J28,2))/10 | L34: =VALUE(RIGHT(Исходник!K28,2))/10 | M34: =VALUE(RIGHT(Исходник!L28,2))/10 | ... AK34: =VALUE(RIGHT(Исходник!AJ28,2))/10 | AO34: 10 | AP34: LAST ENG STOPPED
C35: =Исходник!B29 | F35: =Исходник!E29 | G35: =Исходник!F29 | H35: =Исходник!G29 | I35: =Исходник!H29 | J35: =Исходник!I29 | K35: =Исходник!J29 | L35: =Исходник!K29 | M35: =Исходник!L29 | ... AK35: =Исходник!AJ29 | AO35: 255 | AP35: UNINIT
C36: =Исходник!B30 | F36: =Исходник!E30 | G36: =Исходник!F30 | H36: =Исходник!G30 | I36: =Исходник!H30 | J36: =Исходник!I30 | K36: =Исходник!J30 | L36: =Исходник!K30 | M36: =Исходник!L30 | ... AK36: =Исходник!AJ30
C37: =Исходник!B31 | F37: =Исходник!E31 | G37: =Исходник!F31 | H37: =Исходник!G31 | I37: =Исходник!H31 | J37: =Исходник!I31 | K37: =Исходник!J31 | L37: =Исходник!K31 | M37: =Исходник!L31 | ... AK37: =Исходник!AJ31
C38: LRU MESSAGE | F38: =VLOOKUP(HEX2DEC(RIGHT(Исходник!E32,2)),$AO$39:$AP$60,2,0) | G38: =VLOOKUP(HEX2DEC(RIGHT(Исходник!F32,2)),$AO$39:$AP$60,2,0) | H38: =VLOOKUP(HEX2DEC(RIGHT(Исходник!G32,2)),$AO$39:$AP$60,2,0) | I38: =VLOOKUP(HEX2DEC(RIGHT(Исходник!H32,2)),$AO$39:$AP$60,2,0) | J38: =VLOOKUP(HEX2DEC(RIGHT(Исходник!I32,2)),$AO$39:$AP$60,2,0) | K38: =VLOOKUP(HEX2DEC(RIGHT(Исходник!J32,2)),$AO$39:$AP$60,2,0) | L38: =VLOOKUP(HEX2DEC(RIGHT(Исходник!K32,2)),$AO$39:$AP$60,2,0) | M38: =VLOOKUP(HEX2DEC(RIGHT(Исходник!L32,2)),$AO$39:$AP$60,2,0) | ... AK38: =VLOOKUP(HEX2DEC(RIGHT(Исходник!AJ32,2)),$AO$39:$AP$60,2,0) | AO38: LRU MESSAGE
C39: =Исходник!B33 | F39: =TEXT(HEX2BIN(RIGHT(Исходник!E33,2)),"00000000") | G39: =TEXT(HEX2BIN(RIGHT(Исходник!F33,2)),"00000000") | H39: =TEXT(HEX2BIN(RIGHT(Исходник!G33,2)),"00000000") | I39: =TEXT(HEX2BIN(RIGHT(Исходник!H33,2)),"00000000") | J39: =TEXT(HEX2BIN(RIGHT(Исходник!I33,2)),"00000000") | K39: =TEXT(HEX2BIN(RIGHT(Исходник!J33,2)),"00000000") | L39: =TEXT(HEX2BIN(RIGHT(Исходник!K33,2)),"00000000") | M39: =TEXT(HEX2BIN(RIGHT(Исходник!L33,2)),"00000000") | ... AK39: =TEXT(HEX2BIN(RIGHT(Исходник!AJ33,2)),"00000000") | AO39: 0 | AP39: NO FAILURE DATA STORED OR OBSOLETE FAILURE DATA
C40: =Исходник!B34 | F40: =TEXT(HEX2BIN(RIGHT(Исходник!E34,2)),"00000000") | G40: =TEXT(HEX2BIN(RIGHT(Исходник!F34,2)),"00000000") | H40: =TEXT(HEX2BIN(RIGHT(Исходник!G34,2)),"00000000") | I40: =TEXT(HEX2BIN(RIGHT(Исходник!H34,2)),"00000000") | J40: =TEXT(HEX2BIN(RIGHT(Исходник!I34,2)),"00000000") | K40: =TEXT(HEX2BIN(RIGHT(Исходник!J34,2)),"00000000") | L40: =TEXT(HEX2BIN(RIGHT(Исходник!K34,2)),"00000000") | M40: =TEXT(HEX2BIN(RIGHT(Исходник!L34,2)),"00000000") | ... AK40: =TEXT(HEX2BIN(RIGHT(Исходник!AJ34,2)),"00000000") | AO40: 1 | AP40: OUTFLOW VALVE ELECTRONIC
...

Sheet Исходник
A2: S/N | B2: 0854763
E4: 0 | F4: =E4+1 | G4: =F4+1 | H4: =G4+1 | I4: =H4+1 | J4: =I4+1 | K4: =J4+1 | L4: =K4+1 | M4: =L4+1 | ... AJ4: =AI4+1
B5: FAULT CODE | E5: =com!A1 | F5: =com!A42 | G5: =com!A83 | H5: =com!A124 | I5: =com!A165 | J5: =com!A206 | K5: =com!A247 | L5: =com!A288 | M5: =com!A329 | N5: =com!A370 | O5: =com!A411 | P5: =com!A452 | Q5: =com!A493 | R5: =com!A534 | S5: =com!A575 | T5: =com!A616 | U5: =com!A657 | V5: =com!A698 | W5: =com!A739 | X5: =com!A780 | Y5: =com!A821 | Z5: =com!A862 | AA5: =com!A903 | AB5: =com!A944 | AC5: =com!A985 | AD5: =com!A1026 | AE5: =com!A1067 | AF5: =com!A1108 | AG5: =com!A1149 | AH5: =com!A1190 | AI5: =com!A1231 | AJ5: =com!A1272
B6: INTERNAL FLIGHT LEG - LSB | E6: =com!A2 | F6: =com!A43 | G6: =com!A84 | H6: =com!A125 | I6: =com!A166 | J6: =com!A207 | K6: =com!A248 | L6: =com!A289 | M6: =com!A330 | N6: =com!A371 | O6: =com!A412 | P6: =com!A453 | Q6: =com!A494 | R6: =com!A535 | S6: =com!A576 | T6: =com!A617 | U6: =com!A658 | V6: =com!A699 | W6: =com!A740 | X6: =com!A781 | Y6: =com!A822 | Z6: =com!A863 | AA6: =com!A904 | AB6: =com!A945 | AC6: =com!A986 | AD6: =com!A1027 | AE6: =com!A1068 | AF6: =com!A1109 | AG6: =com!A1150 | AH6: =com!A1191 | AI6: =com!A1232 | AJ6: =com!A1273
B7: INTERNAL FLIGHT LEG - MSB | E7: =com!A3 | F7: =com!A44 | G7: =com!A85 | H7: =com!A126 | I7: =com!A167 | J7: =com!A208 | K7: =com!A249 | L7: =com!A290 | M7: =com!A331 | N7: =com!A372 | O7: =com!A413 | P7: =com!A454 | Q7: =com!A495 | R7: =com!A536 | S7: =com!A577 | T7: =com!A618 | U7: =com!A659 | V7: =com!A700 | W7: =com!A741 | X7: =com!A782 | Y7: =com!A823 | Z7: =com!A864 | AA7: =com!A905 | AB7: =com!A946 | AC7: =com!A987 | AD7: =com!A1028 | AE7: =com!A1069 | AF7: =com!A1110 | AG7: =com!A1151 | AH7: =com!A1192 | AI7: =com!A1233 | AJ7: =com!A1274
B8: INTERNAL FLIGHT MODE | E8: =com!A4 | F8: =com!A45 | G8: =com!A86 | H8: =com!A127 | I8: =com!A168 | J8: =com!A209 | K8: =com!A250 | L8: =com!A291 | M8: =com!A332 | N8: =com!A373 | O8: =com!A414 | P8: =com!A455 | Q8: =com!A496 | R8: =com!A537 | S8: =com!A578 | T8: =com!A619 | U8: =com!A660 | V8: =com!A701 | W8: =com!A742 | X8: =com!A783 | Y8: =com!A824 | Z8: =com!A865 | AA8: =com!A906 | AB8: =com!A947 | AC8: =com!A988 | AD8: =com!A1029 | AE8: =com!A1070 | AF8: =com!A1111 | AG8: =com!A1152 | AH8: =com!A1193 | AI8: =com!A1234 | AJ8: =com!A1275
B9: INTERMITTENT COUNT | E9: =com!A5 | F9: =com!A46 | G9: =com!A87 | H9: =com!A128 | I9: =com!A169 | J9: =com!A210 | K9: =com!A251 | L9: =com!A292 | M9: =com!A333 | N9: =com!A374 | O9: =com!A415 | P9: =com!A456 | Q9: =com!A497 | R9: =com!A538 | S9: =com!A579 | T9: =com!A620 | U9: =com!A661 | V9: =com!A702 | W9: =com!A743 | X9: =com!A784 | Y9: =com!A825 | Z9: =com!A866 | AA9: =com!A907 | AB9: =com!A948 | AC9: =com!A989 | AD9: =com!A1030 | AE9: =com!A1071 | AF9: =com!A1112 | AG9: =com!A1153 | AH9: =com!A1194 | AI9: =com!A1235 | AJ9: =com!A1276
B10: FLIGHT PHASE | E10: =com!A6 | F10: =com!A47 | G10: =com!A88 | H10: =com!A129 | I10: =com!A170 | J10: =com!A211 | K10: =com!A252 | L10: =com!A293 | M10: =com!A334 | N10: =com!A375 | O10: =com!A416 | P10: =com!A457 | Q10: =com!A498 | R10: =com!A539 | S10: =com!A580 | T10: =com!A621 | U10: =com!A662 | V10: =com!A703 | W10: =com!A744 | X10: =com!A785 | Y10: =com!A826 | Z10: =com!A867 | AA10: =com!A908 | AB10: =com!A949 | AC10: =com!A990 | AD10: =com!A1031 | AE10: =com!A1072 | AF10: =com!A1113 | AG10: =com!A1154 | AH10: =com!A1195 | AI10: =com!A1236 | AJ10: =com!A1277
B11: A/C IDENTIFICATION 1st character | E11: =com!A7 | F11: =com!A48 | G11: =com!A89 | H11: =com!A130 | I11: =com!A171 | J11: =com!A212 | K11: =com!A253 | L11: =com!A294 | M11: =com!A335 | N11: =com!A376 | O11: =com!A417 | P11: =com!A458 | Q11: =com!A499 | R11: =com!A540 | S11: =com!A581 | T11: =com!A622 | U11: =com!A663 | V11: =com!A704 | W11: =com!A745 | X11: =com!A786 | Y11: =com!A827 | Z11: =com!A868 | AA11: =com!A909 | AB11: =com!A950 | AC11: =com!A991 | AD11: =com!A1032 | AE11: =com!A1073 | AF11: =com!A1114 | AG11: =com!A1155 | AH11: =com!A1196 | AI11: =com!A1237 | AJ11: =com!A1278
B12: A/C IDENTIFICATION 2nd character | E12: =com!A8 | F12: =com!A49 | G12: =com!A90 | H12: =com!A131 | I12: =com!A172 | J12: =com!A213 | K12: =com!A254 | L12: =com!A295 | M12: =com!A336 | N12: =com!A377 | O12: =com!A418 | P12: =com!A459 | Q12: =com!A500 | R12: =com!A541 | S12: =com!A582 | T12: =com!A623 | U12: =com!A664 | V12: =com!A705 | W12: =com!A746 | X12: =com!A787 | Y12: =com!A828 | Z12: =com!A869 | AA12: =com!A910 | AB12: =com!A951 | AC12: =com!A992 | AD12: =com!A1033 | AE12: =com!A1074 | AF12: =com!A1115 | AG12: =com!A1156 | AH12: =com!A1197 | AI12: =com!A1238 | AJ12: =com!A1279
B13: A/C IDENTIFICATION 3rd character | E13: =com!A9 | F13: =com!A50 | G13: =com!A91 | H13: =com!A132 | I13: =com!A173 | J13: =com!A214 | K13: =com!A255 | L13: =com!A296 | M13: =com!A337 | N13: =com!A378 | O13: =com!A419 | P13: =com!A460 | Q13: =com!A501 | R13: =com!A542 | S13: =com!A583 | T13: =com!A624 | U13: =com!A665 | V13: =com!A706 | W13: =com!A747 | X13: =com!A788 | Y13: =com!A829 | Z13: =com!A870 | AA13: =com!A911 | AB13: =com!A952 | AC13: =com!A993 | AD13: =com!A1034 | AE13: =com!A1075 | AF13: =com!A1116 | AG13: =com!A1157 | AH13: =com!A1198 | AI13: =com!A1239 | AJ13: =com!A1280
B14: A/C IDENTIFICATION 4th character | E14: =com!A10 | F14: =com!A51 | G14: =com!A92 | H14: =com!A133 | I14: =com!A174 | J14: =com!A215 | K14: =com!A256 | L14: =com!A297 | M14: =com!A338 | N14: =com!A379 | O14: =com!A420 | P14: =com!A461 | Q14: =com!A502 | R14: =com!A543 | S14: =com!A584 | T14: =com!A625 | U14: =com!A666 | V14: =com!A707 | W14: =com!A748 | X14: =com!A789 | Y14: =com!A830 | Z14: =com!A871 | AA14: =com!A912 | AB14: =com!A953 | AC14: =com!A994 | AD14: =com!A1035 | AE14: =com!A1076 | AF14: =com!A1117 | AG14: =com!A1158 | AH14: =com!A1199 | AI14: =com!A1240 | AJ14: =com!A1281
B15: A/C IDENTIFICATION 5th character | E15: =com!A11 | F15: =com!A52 | G15: =com!A93 | H15: =com!A134 | I15: =com!A175 | J15: =com!A216 | K15: =com!A257 | L15: =com!A298 | M15: =com!A339 | N15: =com!A380 | O15: =com!A421 | P15: =com!A462 | Q15: =com!A503 | R15: =com!A544 | S15: =com!A585 | T15: =com!A626 | U15: =com!A667 | V15: =com!A708 | W15: =com!A749 | X15: =com!A790 | Y15: =com!A831 | Z15: =com!A872 | AA15: =com!A913 | AB15: =com!A954 | AC15: =com!A995 | AD15: =com!A1036 | AE15: =com!A1077 | AF15: =com!A1118 | AG15: =com!A1159 | AH15: =com!A1200 | AI15: =com!A1241 | AJ15: =com!A1282
B16: A/C IDENTIFICATION 6th character | E16: =com!A12 | F16: =com!A53 | G16: =com!A94 | H16: =com!A135 | I16: =com!A176 | J16: =com!A217 | K16: =com!A258 | L16: =com!A299 | M16: =com!A340 | N16: =com!A381 | O16: =com!A422 | P16: =com!A463 | Q16: =com!A504 | R16: =com!A545 | S16: =com!A586 | T16: =com!A627 | U16: =com!A668 | V16: =com!A709 | W16: =com!A750 | X16: =com!A791 | Y16: =com!A832 | Z16: =com!A873 | AA16: =com!A914 | AB16: =com!A955 | AC16: =com!A996 | AD16: =com!A1037 | AE16: =com!A1078 | AF16: =com!A1119 | AG16: =com!A1160 | AH16: =com!A1201 | AI16: =com!A1242 | AJ16: =com!A1283
... B24: FLIGHT No. 7th character | E24: =com!A20 | F24: =com!A61 | G24: =com!A102 | H24: =com!A143 | I24: =com!A184 | J24: =com!A225 | K24: =com!A266 | L24: =com!A307 | M24: =com!A348 | N24: =com!A389 | O24: =com!A430 | P24: =com!A471 | Q24: =com!A512 | R24: =com!A553 | S24: =com!A594 | T24: =com!A635 | U24: =com!A676 | V24: =com!A717 | W24: =com!A758 | X24: =com!A799 | Y24: =com!A840 | Z24: =com!A881 | AA24: =com!A922 | AB24: =com!A963 | AC24: =com!A1004 | AD24: =com!A1045 | AE24: =com!A1086 | AF24: =com!A1127 | AG24: =com!A1168 | AH24: =com!A1209 | AI24: =com!A1250 | AJ24: =com!A1291
B25: FLIGHT No. 8th character | D25: =CHAR(HEX2DEC(E25)) | E25: =com!A21 | F25: =com!A62 | G25: =com!A103 | H25: =com!A144 | I25: =com!A185 | J25: =com!A226 | K25: =com!A267 | L25: =com!A308 | M25: =com!A349 | N25: =com!A390 | O25: =com!A431 | P25: =com!A472 | Q25: =com!A513 | R25: =com!A554 | S25: =com!A595 | T25: =com!A636 | U25: =com!A677 | V25: =com!A718 | W25: =com!A759 | X25: =com!A800 | Y25: =com!A841 | Z25: =com!A882 | AA25: =com!A923 | AB25: =com!A964 | AC25: =com!A1005 | AD25: =com!A1046 | AE25: =com!A1087 | AF25: =com!A1128 | AG25: =com!A1169 | AH25: =com!A1210 | AI25: =com!A1251 | AJ25: =com!A1292
B26: GREENWICH MEAN TIME, hours | E26: =com!A22 | F26: =com!A63 | G26: =com!A104 | H26: =com!A145 | I26: =com!A186 | J26: =com!A227 | K26: =com!A268 | L26: =com!A309 | M26: =com!A350 | N26: =com!A391 | O26: =com!A432 | P26: =com!A473 | Q26: =com!A514 | R26: =com!A555 | S26: =com!A596 | T26: =com!A637 | U26: =com!A678 | V26: =com!A719 | W26: =com!A760 | X26: =com!A801 | Y26: =com!A842 | Z26: =com!A883 | AA26: =com!A924 | AB26: =com!A965 | AC26: =com!A1006 | AD26: =com!A1047 | AE26: =com!A1088 | AF26: =com!A1129 | AG26: =com!A1170 | AH26: =com!A1211 | AI26: =com!A1252 | AJ26: =com!A1293
B27: GREENWICH MEAN TIME, minutes | E27: =com!A23 | F27: =com!A64 | G27: =com!A105 | H27: =com!A146 | I27: =com!A187 | J27: =com!A228 | K27: =com!A269 | L27: =com!A310 | M27: =com!A351 | N27: =com!A392 | O27: =com!A433 | P27: =com!A474 | Q27: =com!A515 | R27: =com!A556 | S27: =com!A597 | T27: =com!A638 | U27: =com!A679 | V27: =com!A720 | W27: =com!A761 | X27: =com!A802 | Y27: =com!A843 | Z27: =com!A884 | AA27: =com!A925 | AB27: =com!A966 | AC27: =com!A1007 | AD27: =com!A1048 | AE27: =com!A1089 | AF27: =com!A1130 | AG27: =com!A1171 | AH27: =com!A1212 | AI27: =com!A1253 | AJ27: =com!A1294
B28: GREENWICH MEAN TIME, seconds | E28: =com!A24 | F28: =com!A65 | G28: =com!A106 | H28: =com!A147 | I28: =com!A188 | J28: =com!A229 | K28: =com!A270 | L28: =com!A311 | M28: =com!A352 | N28: =com!A393 | O28: =com!A434 | P28: =com!A475 | Q28: =com!A516 | R28: =com!A557 | S28: =com!A598 | T28: =com!A639 | U28: =com!A680 | V28: =com!A721 | W28: =com!A762 | X28: =com!A803 | Y28: =com!A844 | Z28: =com!A885 | AA28: =com!A926 | AB28: =com!A967 | AC28: =com!A1008 | AD28: =com!A1049 | AE28: =com!A1090 | AF28: =com!A1131 | AG28: =com!A1172 | AH28: =com!A1213 | AI28: =com!A1254 | AJ28: =com!A1295
B29: DATE, day | E29: =com!A25 | F29: =com!A66 | G29: =com!A107 | H29: =com!A148 | I29: =com!A189 | J29: =com!A230 | K29: =com!A271 | L29: =com!A312 | M29: =com!A353 | N29: =com!A394 | O29: =com!A435 | P29: =com!A476 | Q29: =com!A517 | R29: =com!A558 | S29: =com!A599 | T29: =com!A640 | U29: =com!A681 | V29: =com!A722 | W29: =com!A763 | X29: =com!A804 | Y29: =com!A845 | Z29: =com!A886 | AA29: =com!A927 | AB29: =com!A968 | AC29: =com!A1009 | AD29: =com!A1050 | AE29: =com!A1091 | AF29: =com!A1132 | AG29: =com!A1173 | AH29: =com!A1214 | AI29: =com!A1255 | AJ29: =com!A1296
B30: DATE, month | E30: =com!A26 | F30: =com!A67 | G30: =com!A108 | H30: =com!A149 | I30: =com!A190 | J30: =com!A231 | K30: =com!A272 | L30: =com!A313 | M30: =com!A354 | N30: =com!A395 | O30: =com!A436 | P30: =com!A477 | Q30: =com!A518 | R30: =com!A559 | S30: =com!A600 | T30: =com!A641 | U30: =com!A682 | V30: =com!A723 | W30: =com!A764 | X30: =com!A805 | Y30: =com!A846 | Z30: =com!A887 | AA30: =com!A928 | AB30: =com!A969 | AC30: =com!A1010 | AD30: =com!A1051 | AE30: =com!A1092 | AF30: =com!A1133 | AG30: =com!A1174 | AH30: =com!A1215 | AI30: =com!A1256 | AJ30: =com!A1297
B31: DATE, year | E31: =com!A27 | F31: =com!A68 | G31: =com!A109 | H31: =com!A150 | I31: =com!A191 | J31: =com!A232 | K31: =com!A273 | L31: =com!A314 | M31: =com!A355 | N31: =com!A396 | O31: =com!A437 | P31: =com!A478 | Q31: =com!A519 | R31: =com!A560 | S31: =com!A601 | T31: =com!A642 | U31: =com!A683 | V31: =com!A724 | W31: =com!A765 | X31: =com!A806 | Y31: =com!A847 | Z31: =com!A888 | AA31: =com!A929 | AB31: =com!A970 | AC31: =com!A1011 | AD31: =com!A1052 | AE31: =com!A1093 | AF31: =com!A1134 | AG31: =com!A1175 | AH31: =com!A1216 | AI31: =com!A1257 | AJ31: =com!A1298
B32: INTERNAL LRU NUMBER | E32: =com!A28 | F32: =com!A69 | G32: =com!A110 | H32: =com!A151 | I32: =com!A192 | J32: =com!A233 | K32: =com!A274 | L32: =com!A315 | M32: =com!A356 | N32: =com!A397 | O32: =com!A438 | P32: =com!A479 | Q32: =com!A520 | R32: =com!A561 | S32: =com!A602 | T32: =com!A643 | U32: =com!A684 | V32: =com!A725 | W32: =com!A766 | X32: =com!A807 | Y32: =com!A848 | Z32: =com!A889 | AA32: =com!A930 | AB32: =com!A971 | AC32: =com!A1012 | AD32: =com!A1053 | AE32: =com!A1094 | AF32: =com!A1135 | AG32: =com!A1176 | AH32: =com!A1217 | AI32: =com!A1258 | AJ32: =com!A1299
B33: BIT FAULT MATRIX, LSB of 1st word | E33: =com!A29 | F33: =com!A70 | G33: =com!A111 | H33: =com!A152 | I33: =com!A193 | J33: =com!A234 | K33: =com!A275 | L33: =com!A316 | M33: =com!A357 | N33: =com!A398 | O33: =com!A439 | P33: =com!A480 | Q33: =com!A521 | R33: =com!A562 | S33: =com!A603 | T33: =com!A644 | U33: =com!A685 | V33: =com!A726 | W33: =com!A767 | X33: =com!A808 | Y33: =com!A849 | Z33: =com!A890 | AA33: =com!A931 | AB33: =com!A972 | AC33: =com!A1013 | AD33: =com!A1054 | AE33: =com!A1095 | AF33: =com!A1136 | AG33: =com!A1177 | AH33: =com!A1218 | AI33: =com!A1259 | AJ33: =com!A1300
B34: BIT FAULT MATRIX, MSB of 1st word | E34: =com!A30 | F34: =com!A71 | G34: =com!A112 | H34: =com!A153 | I34: =com!A194 | J34: =com!A235 | K34: =com!A276 | L34: =com!A317 | M34: =com!A358 | N34: =com!A399 | O34: =com!A440 | P34: =com!A481 | Q34: =com!A522 | R34: =com!A563 | S34: =com!A604 | T34: =com!A645 | U34: =com!A686 | V34: =com!A727 | W34: =com!A768 | X34: =com!A809 | Y34: =com!A850 | Z34: =com!A891 | AA34: =com!A932 | AB34: =com!A973 | AC34: =com!A1014 | AD34: =com!A1055 | AE34: =com!A1096 | AF34: =com!A1137 | AG34: =com!A1178 | AH34: =com!A1219 | AI34: =com!A1260 | AJ34: =com!A1301
B35: BIT FAULT MATRIX, LSB of 2nd word | E35: =com!A31 | F35: =com!A72 | G35: =com!A113 | H35: =com!A154 | I35: =com!A195 | J35: =com!A236 | K35: =com!A277 | L35: =com!A318 | M35: =com!A359 | N35: =com!A400 | O35: =com!A441 | P35: =com!A482 | Q35: =com!A523 | R35: =com!A564 | S35: =com!A605 | T35: =com!A646 | U35: =com!A687 | V35: =com!A728 | W35: =com!A769 | X35: =com!A810 | Y35: =com!A851 | Z35: =com!A892 | AA35: =com!A933 | AB35: =com!A974 | AC35: =com!A1015 | AD35: =com!A1056 | AE35: =com!A1097 | AF35: =com!A1138 | AG35: =com!A1179 | AH35: =com!A1220 | AI35: =com!A1261 | AJ35: =com!A1302
B36: BIT FAULT MATRIX, MSB of 2nd word | E36: =com!A32 | F36: =com!A73 | G36: =com!A114 | H36: =com!A155 | I36: =com!A196 | J36: =com!A237 | K36: =com!A278 | L36: =com!A319 | M36: =com!A360 | N36: =com!A401 | O36: =com!A442 | P36: =com!A483 | Q36: =com!A524 | R36: =com!A565 | S36: =com!A606 | T36: =com!A647 | U36: =com!A688 | V36: =com!A729 | W36: =com!A770 | X36: =com!A811 | Y36: =com!A852 | Z36: =com!A893 | AA36: =com!A934 | AB36: =com!A975 | AC36: =com!A1016 | AD36: =com!A1057 | AE36: =com!A1098 | AF36: =com!A1139 | AG36: =com!A1180 | AH36: =com!A1221 | AI36: =com!A1262 | AJ36: =com!A1303
B37: BIT FAULT MATRIX, LSB of 3rd word | E37: =com!A33 | F37: =com!A74 | G37: =com!A115 | H37: =com!A156 | I37: =com!A197 | J37: =com!A238 | K37: =com!A279 | L37: =com!A320 | M37: =com!A361 | N37: =com!A402 | O37: =com!A443 | P37: =com!A484 | Q37: =com!A525 | R37: =com!A566 | S37: =com!A607 | T37: =com!A648 | U37: =com!A689 | V37: =com!A730 | W37: =com!A771 | X37: =com!A812 | Y37: =com!A853 | Z37: =com!A894 | AA37: =com!A935 | AB37: =com!A976 | AC37: =com!A1017 | AD37: =com!A1058 | AE37: =com!A1099 | AF37: =com!A1140 | AG37: =com!A1181 | AH37: =com!A1222 | AI37: =com!A1263 | AJ37: =com!A1304
... B45: FAILURE CLASS | E45: =com!A41 | F45: =com!A82 | G45: =com!A123 | H45: =com!A164 | I45: =com!A205 | J45: =com!A246 | K45: =com!A287 | L45: =com!A328 | M45: =com!A369 | N45: =com!A410 | O45: =com!A451 | P45: =com!A492 | Q45: =com!A533 | R45: =com!A574 | S45: =com!A615 | T45: =com!A656 | U45: =com!A697 | V45: =com!A738 | W45: =com!A779 | X45: =com!A820 | Y45: =com!A861 | Z45: =com!A902 | AA45: =com!A943 | AB45: =com!A984 | AC45: =com!A1025 | AD45: =com!A1066 | AE45: =com!A1107 | AF45: =com!A1148 | AG45: =com!A1189 | AH45: =com!A1230 | AI45: =com!A1271 | AJ45: =com!A1312

Sheet com
A1: 34
A2: 00
A3: 00
A4: 00
A5: 04
A6: 00
A7: 4E
A8: 4F
A9: 52
A10: 44
A11: 4D
A12: 49
... A1344: 00

Sheet source
Y7: 32 | Z7: =Y7-1 | AA7: =Z7-1 | AB7: =AA7-1 | AC7: =AB7-1 | AD7: =AC7-1 | AE7: =AD7-1 | AF7: =AE7-1 | AG7: =AF7-1 | ... BD7: =BC7-1
D8: Word | E8: SDAC 1 | M8: 31..28 | N8: 27..24 | O8: 23..20 | P8: 19..16 | Q8: 15..12 | R8: 11..8 | S8: 7..4 | T8: 3..0 | Y8: P | Z8: M | AB8: DATA | AW8: lab | AZ8: lab | BC8: lab
D9: 057 | E9: 17980AF4 | M9: =HEX2BIN(MID($E9,COLUMN()-(COLUMN($M9)-1),1),4) | N9: =HEX2BIN(MID($E9,COLUMN()-(COLUMN($M9)-1),1),4) | O9: =HEX2BIN(MID($E9,COLUMN()-(COLUMN($M9)-1),1),4) | P9: =HEX2BIN(MID($E9,COLUMN()-(COLUMN($M9)-1),1),4) | Q9: =HEX2BIN(MID($E9,COLUMN()-(COLUMN($M9)-1),1),4) | R9: =HEX2BIN(MID($E9,COLUMN()-(COLUMN($M9)-1),1),4) | S9: =HEX2BIN(MID($E9,COLUMN()-(COLUMN($M9)-1),1),4) | T9: =HEX2BIN(MID($E9,COLUMN()-(COLUMN($M9)-1),1),4) | Y9: =MID($M9,COLUMN()-(COLUMN($Y9)-1),1) | Z9: =MID($M9,COLUMN()-(COLUMN($Y9)-1),1) | AA9: =MID($M9,COLUMN()-(COLUMN($Y9)-1),1) | AB9: =MID($M9,COLUMN()-(COLUMN($Y9)-1),1) | AC9: =MID($N9,COLUMN()-(COLUMN($AC9)-1),1) | AD9: =MID($N9,COLUMN()-(COLUMN($AC9)-1),1) | AE9: =MID($N9,COLUMN()-(COLUMN($AC9)-1),1) | AF9: =MID($N9,COLUMN()-(COLUMN($AC9)-1),1) | AG9: =MID($O9,COLUMN()-(COLUMN($AG9)-1),1) | AH9: =MID($O9,COLUMN()-(COLUMN($AG9)-1),1) | AI9: =MID($O9,COLUMN()-(COLUMN($AG9)-1),1) | AJ9: =MID($O9,COLUMN()-(COLUMN($AG9)-1),1) | AK9: =MID($P9,COLUMN()-(COLUMN($AK9)-1),1) | AL9: =MID($P9,COLUMN()-(COLUMN($AK9)-1),1) | AM9: =MID($P9,COLUMN()-(COLUMN($AK9)-1),1) | AN9: =MID($P9,COLUMN()-(COLUMN($AK9)-1),1) | AO9: =MID($Q9,COLUMN()-(COLUMN($AO9)-1),1) | AP9: =MID($Q9,COLUMN()-(COLUMN($AO9)-1),1) | AQ9: =MID($Q9,COLUMN()-(COLUMN($AO9)-1),1) | AR9: =MID($Q9,COLUMN()-(COLUMN($AO9)-1),1) | AS9: =MID($R9,COLUMN()-(COLUMN($AS9)-1),1) | AT9: =MID($R9,COLUMN()-(COLUMN($AS9)-1),1) | AU9: =MID($R9,COLUMN()-(COLUMN($AS9)-1),1) | AV9: =MID($R9,COLUMN()-(COLUMN($AS9)-1),1) | AW9: =MID($S9,COLUMN()-(COLUMN($AW9)-1),1) | AX9: =MID($S9,COLUMN()-(COLUMN($AW9)-1),1) | AY9: =MID($S9,COLUMN()-(COLUMN($AW9)-1),1) | AZ9: =MID($S9,COLUMN()-(COLUMN($AW9)-1),1) | BA9: =MID($T9,COLUMN()-(COLUMN($BA9)-1),1) | BB9: =MID($T9,COLUMN()-(COLUMN($BA9)-1),1) | BC9: =MID($T9,COLUMN()-(COLUMN($BA9)-1),1) | BD9: =MID($T9,COLUMN()-(COLUMN($BA9)-1),1)
D10: 104 | E10: 00180222 | M10: =HEX2BIN(MID($E10,COLUMN()-(COLUMN($M10)-1),1),4) | N10: =HEX2BIN(MID($E10,COLUMN()-(COLUMN($M10)-1),1),4) | O10: =HEX2BIN(MID($E10,COLUMN()-(COLUMN($M10)-1),1),4) | P10: =HEX2BIN(MID($E10,COLUMN()-(COLUMN($M10)-1),1),4) | Q10: =HEX2BIN(MID($E10,COLUMN()-(COLUMN($M10)-1),1),4) | R10: =HEX2BIN(MID($E10,COLUMN()-(COLUMN($M10)-1),1),4) | S10: =HEX2BIN(MID($E10,COLUMN()-(COLUMN($M10)-1),1),4) | T10: =HEX2BIN(MID($E10,COLUMN()-(COLUMN($M10)-1),1),4) | Y10: =MID($M10,COLUMN()-(COLUMN($Y10)-1),1) | Z10: =MID($M10,COLUMN()-(COLUMN($Y10)-1),1) | AA10: =MID($M10,COLUMN()-(COLUMN($Y10)-1),1) | AB10: =MID($M10,COLUMN()-(COLUMN($Y10)-1),1) | AC10: =MID($N10,COLUMN()-(COLUMN($AC10)-1),1) | AD10: =MID($N10,COLUMN()-(COLUMN($AC10)-1),1) | AE10: =MID($N10,COLUMN()-(COLUMN($AC10)-1),1) | AF10: =MID($N10,COLUMN()-(COLUMN($AC10)-1),1) | AG10: =MID($O10,COLUMN()-(COLUMN($AG10)-1),1) | AH10: =MID($O10,COLUMN()-(COLUMN($AG10)-1),1) | AI10: =MID($O10,COLUMN()-(COLUMN($AG10)-1),1) | AJ10: =MID($O10,COLUMN()-(COLUMN($AG10)-1),1) | AK10: =MID($P10,COLUMN()-(COLUMN($AK10)-1),1) | AL10: =MID($P10,COLUMN()-(COLUMN($AK10)-1),1) | AM10: =MID($P10,COLUMN()-(COLUMN($AK10)-1),1) | AN10: =MID($P10,COLUMN()-(COLUMN($AK10)-1),1) | AO10: =MID($Q10,COLUMN()-(COLUMN($AO10)-1),1) | AP10: =MID($Q10,COLUMN()-(COLUMN($AO10)-1),1) | AQ10: =MID($Q10,COLUMN()-(COLUMN($AO10)-1),1) | AR10: =MID($Q10,COLUMN()-(COLUMN($AO10)-1),1) | AS10: =MID($R10,COLUMN()-(COLUMN($AS10)-1),1) | AT10: =MID($R10,COLUMN()-(COLUMN($AS10)-1),1) | AU10: =MID($R10,COLUMN()-(COLUMN($AS10)-1),1) | AV10: =MID($R10,COLUMN()-(COLUMN($AS10)-1),1) | AW10: =MID($S10,COLUMN()-(COLUMN($AW10)-1),1) | AX10: =MID($S10,COLUMN()-(COLUMN($AW10)-1),1) | AY10: =MID($S10,COLUMN()-(COLUMN($AW10)-1),1) | AZ10: =MID($S10,COLUMN()-(COLUMN($AW10)-1),1) | BA10: =MID($T10,COLUMN()-(COLUMN($BA10)-1),1) | BB10: =MID($T10,COLUMN()-(COLUMN($BA10)-1),1) | BC10: =MID($T10,COLUMN()-(COLUMN($BA10)-1),1) | BD10: =MID($T10,COLUMN()-(COLUMN($BA10)-1),1)
D11: 105 | E11: 0022E2A2 | M11: =HEX2BIN(MID($E11,COLUMN()-(COLUMN($M11)-1),1),4) | N11: =HEX2BIN(MID($E11,COLUMN()-(COLUMN($M11)-1),1),4) | O11: =HEX2BIN(MID($E11,COLUMN()-(COLUMN($M11)-1),1),4) | P11: =HEX2BIN(MID($E11,COLUMN()-(COLUMN($M11)-1),1),4) | Q11: =HEX2BIN(MID($E11,COLUMN()-(COLUMN($M11)-1),1),4) | R11: =HEX2BIN(MID($E11,COLUMN()-(COLUMN($M11)-1),1),4) | S11: =HEX2BIN(MID($E11,COLUMN()-(COLUMN($M11)-1),1),4) | T11: =HEX2BIN(MID($E11,COLUMN()-(COLUMN($M11)-1),1),4) | Y11: =MID($M11,COLUMN()-(COLUMN($Y11)-1),1) | Z11: =MID($M11,COLUMN()-(COLUMN($Y11)-1),1) | AA11: =MID($M11,COLUMN()-(COLUMN($Y11)-1),1) | AB11: =MID($M11,COLUMN()-(COLUMN($Y11)-1),1) | AC11: =MID($N11,COLUMN()-(COLUMN($AC11)-1),1) | AD11: =MID($N11,COLUMN()-(COLUMN($AC11)-1),1) | AE11: =MID($N11,COLUMN()-(COLUMN($AC11)-1),1) | AF11: =MID($N11,COLUMN()-(COLUMN($AC11)-1),1) | AG11: =MID($O11,COLUMN()-(COLUMN($AG11)-1),1) | AH11: =MID($O11,COLUMN()-(COLUMN($AG11)-1),1) | AI11: =MID($O11,COLUMN()-(COLUMN($AG11)-1),1) | AJ11: =MID($O11,COLUMN()-(COLUMN($AG11)-1),1) | AK11: =MID($P11,COLUMN()-(COLUMN($AK11)-1),1) | AL11: =MID($P11,COLUMN()-(COLUMN($AK11)-1),1) | AM11: =MID($P11,COLUMN()-(COLUMN($AK11)-1),1) | AN11: =MID($P11,COLUMN()-(COLUMN($AK11)-1),1) | AO11: =MID($Q11,COLUMN()-(COLUMN($AO11)-1),1) | AP11: =MID($Q11,COLUMN()-(COLUMN($AO11)-1),1) | AQ11: =MID($Q11,COLUMN()-(COLUMN($AO11)-1),1) | AR11: =MID($Q11,COLUMN()-(COLUMN($AO11)-1),1) | AS11: =MID($R11,COLUMN()-(COLUMN($AS11)-1),1) | AT11: =MID($R11,COLUMN()-(COLUMN($AS11)-1),1) | AU11: =MID($R11,COLUMN()-(COLUMN($AS11)-1),1) | AV11: =MID($R11,COLUMN()-(COLUMN($AS11)-1),1) | AW11: =MID($S11,COLUMN()-(COLUMN($AW11)-1),1) | AX11: =MID($S11,COLUMN()-(COLUMN($AW11)-1),1) | AY11: =MID($S11,COLUMN()-(COLUMN($AW11)-1),1) | AZ11: =MID($S11,COLUMN()-(COLUMN($AW11)-1),1) | BA11: =MID($T11,COLUMN()-(COLUMN($BA11)-1),1) | BB11: =MID($T11,COLUMN()-(COLUMN($BA11)-1),1) | BC11: =MID($T11,COLUMN()-(COLUMN($BA11)-1),1) | BD11: =MID($T11,COLUMN()-(COLUMN($BA11)-1),1)
D12: 106 | E12: 00500662 | M12: =HEX2BIN(MID($E12,COLUMN()-(COLUMN($M12)-1),1),4) | N12: =HEX2BIN(MID($E12,COLUMN()-(COLUMN($M12)-1),1),4) | O12: =HEX2BIN(MID($E12,COLUMN()-(COLUMN($M12)-1),1),4) | P12: =HEX2BIN(MID($E12,COLUMN()-(COLUMN($M12)-1),1),4) | Q12: =HEX2BIN(MID($E12,COLUMN()-(COLUMN($M12)-1),1),4) | R12: =HEX2BIN(MID($E12,COLUMN()-(COLUMN($M12)-1),1),4) | S12: =HEX2BIN(MID($E12,COLUMN()-(COLUMN($M12)-1),1),4) | T12: =HEX2BIN(MID($E12,COLUMN()-(COLUMN($M12)-1),1),4) | Y12: =MID($M12,COLUMN()-(COLUMN($Y12)-1),1) | Z12: =MID($M12,COLUMN()-(COLUMN($Y12)-1),1) | AA12: =MID($M12,COLUMN()-(COLUMN($Y12)-1),1) | AB12: =MID($M12,COLUMN()-(COLUMN($Y12)-1),1) | AC12: =MID($N12,COLUMN()-(COLUMN($AC12)-1),1) | AD12: =MID($N12,COLUMN()-(COLUMN($AC12)-1),1) | AE12: =MID($N12,COLUMN()-(COLUMN($AC12)-1),1) | AF12: =MID($N12,COLUMN()-(COLUMN($AC12)-1),1) | AG12: =MID($O12,COLUMN()-(COLUMN($AG12)-1),1) | AH12: =MID($O12,COLUMN()-(COLUMN($AG12)-1),1) | AI12: =MID($O12,COLUMN()-(COLUMN($AG12)-1),1) | AJ12: =MID($O12,COLUMN()-(COLUMN($AG12)-1),1) | AK12: =MID($P12,COLUMN()-(COLUMN($AK12)-1),1) | AL12: =MID($P12,COLUMN()-(COLUMN($AK12)-1),1) | AM12: =MID($P12,COLUMN()-(COLUMN($AK12)-1),1) | AN12: =MID($P12,COLUMN()-(COLUMN($AK12)-1),1) | AO12: =MID($Q12,COLUMN()-(COLUMN($AO12)-1),1) | AP12: =MID($Q12,COLUMN()-(COLUMN($AO12)-1),1) | AQ12: =MID($Q12,COLUMN()-(COLUMN($AO12)-1),1) | AR12: =MID($Q12,COLUMN()-(COLUMN($AO12)-1),1) | AS12: =MID($R12,COLUMN()-(COLUMN($AS12)-1),1) | AT12: =MID($R12,COLUMN()-(COLUMN($AS12)-1),1) | AU12: =MID($R12,COLUMN()-(COLUMN($AS12)-1),1) | AV12: =MID($R12,COLUMN()-(COLUMN($AS12)-1),1) | AW12: =MID($S12,COLUMN()-(COLUMN($AW12)-1),1) | AX12: =MID($S12,COLUMN()-(COLUMN($AW12)-1),1) | AY12: =MID($S12,COLUMN()-(COLUMN($AW12)-1),1) | AZ12: =MID($S12,COLUMN()-(COLUMN($AW12)-1),1) | BA12: =MID($T12,COLUMN()-(COLUMN($BA12)-1),1) | BB12: =MID($T12,COLUMN()-(COLUMN($BA12)-1),1) | BC12: =MID($T12,COLUMN()-(COLUMN($BA12)-1),1) | BD12: =MID($T12,COLUMN()-(COLUMN($BA12)-1),1)
D13: 107 | E13: 008322E2 | M13: =HEX2BIN(MID($E13,COLUMN()-(COLUMN($M13)-1),1),4) | N13: =HEX2BIN(MID($E13,COLUMN()-(COLUMN($M13)-1),1),4) | O13: =HEX2BIN(MID($E13,COLUMN()-(COLUMN($M13)-1),1),4) | P13: =HEX2BIN(MID($E13,COLUMN()-(COLUMN($M13)-1),1),4) | Q13: =HEX2BIN(MID($E13,COLUMN()-(COLUMN($M13)-1),1),4) | R13: =HEX2BIN(MID($E13,COLUMN()-(COLUMN($M13)-1),1),4) | S13: =HEX2BIN(MID($E13,COLUMN()-(COLUMN($M13)-1),1),4) | T13: =HEX2BIN(MID($E13,COLUMN()-(COLUMN($M13)-1),1),4) | Y13: =MID($M13,COLUMN()-(COLUMN($Y13)-1),1) | Z13: =MID($M13,COLUMN()-(COLUMN($Y13)-1),1) | AA13: =MID($M13,COLUMN()-(COLUMN($Y13)-1),1) | AB13: =MID($M13,COLUMN()-(COLUMN($Y13)-1),1) | AC13: =MID($N13,COLUMN()-(COLUMN($AC13)-1),1) | AD13: =MID($N13,COLUMN()-(COLUMN($AC13)-1),1) | AE13: =MID($N13,COLUMN()-(COLUMN($AC13)-1),1) | AF13: =MID($N13,COLUMN()-(COLUMN($AC13)-1),1) | AG13: =MID($O13,COLUMN()-(COLUMN($AG13)-1),1) | AH13: =MID($O13,COLUMN()-(COLUMN($AG13)-1),1) | AI13: =MID($O13,COLUMN()-(COLUMN($AG13)-1),1) | AJ13: =MID($O13,COLUMN()-(COLUMN($AG13)-1),1) | AK13: =MID($P13,COLUMN()-(COLUMN($AK13)-1),1) | AL13: =MID($P13,COLUMN()-(COLUMN($AK13)-1),1) | AM13: =MID($P13,COLUMN()-(COLUMN($AK13)-1),1) | AN13: =MID($P13,COLUMN()-(COLUMN($AK13)-1),1) | AO13: =MID($Q13,COLUMN()-(COLUMN($AO13)-1),1) | AP13: =MID($Q13,COLUMN()-(COLUMN($AO13)-1),1) | AQ13: =MID($Q13,COLUMN()-(COLUMN($AO13)-1),1) | AR13: =MID($Q13,COLUMN()-(COLUMN($AO13)-1),1) | AS13: =MID($R13,COLUMN()-(COLUMN($AS13)-1),1) | AT13: =MID($R13,COLUMN()-(COLUMN($AS13)-1),1) | AU13: =MID($R13,COLUMN()-(COLUMN($AS13)-1),1) | AV13: =MID($R13,COLUMN()-(COLUMN($AS13)-1),1) | AW13: =MID($S13,COLUMN()-(COLUMN($AW13)-1),1) | AX13: =MID($S13,COLUMN()-(COLUMN($AW13)-1),1) | AY13: =MID($S13,COLUMN()-(COLUMN($AW13)-1),1) | AZ13: =MID($S13,COLUMN()-(COLUMN($AW13)-1),1) | BA13: =MID($T13,COLUMN()-(COLUMN($BA13)-1),1) | BB13: =MID($T13,COLUMN()-(COLUMN($BA13)-1),1) | BC13: =MID($T13,COLUMN()-(COLUMN($BA13)-1),1) | BD13: =MID($T13,COLUMN()-(COLUMN($BA13)-1),1)
D14: 110 | E14: 00000212 | M14: =HEX2BIN(MID($E14,COLUMN()-(COLUMN($M14)-1),1),4) | N14: =HEX2BIN(MID($E14,COLUMN()-(COLUMN($M14)-1),1),4) | O14: =HEX2BIN(MID($E14,COLUMN()-(COLUMN($M14)-1),1),4) | P14: =HEX2BIN(MID($E14,COLUMN()-(COLUMN($M14)-1),1),4) | Q14: =HEX2BIN(MID($E14,COLUMN()-(COLUMN($M14)-1),1),4) | R14: =HEX2BIN(MID($E14,COLUMN()-(COLUMN($M14)-1),1),4) | S14: =HEX2BIN(MID($E14,COLUMN()-(COLUMN($M14)-1),1),4) | T14: =HEX2BIN(MID($E14,COLUMN()-(COLUMN($M14)-1),1),4) | Y14: =MID($M14,COLUMN()-(COLUMN($Y14)-1),1) | Z14: =MID($M14,COLUMN()-(COLUMN($Y14)-1),1) | AA14: =MID($M14,COLUMN()-(COLUMN($Y14)-1),1) | AB14: =MID($M14,COLUMN()-(COLUMN($Y14)-1),1) | AC14: =MID($N14,COLUMN()-(COLUMN($AC14)-1),1) | AD14: =MID($N14,COLUMN()-(COLUMN($AC14)-1),1) | AE14: =MID($N14,COLUMN()-(COLUMN($AC14)-1),1) | AF14: =MID($N14,COLUMN()-(COLUMN($AC14)-1),1) | AG14: =MID($O14,COLUMN()-(COLUMN($AG14)-1),1) | AH14: =MID($O14,COLUMN()-(COLUMN($AG14)-1),1) | AI14: =MID($O14,COLUMN()-(COLUMN($AG14)-1),1) | AJ14: =MID($O14,COLUMN()-(COLUMN($AG14)-1),1) | AK14: =MID($P14,COLUMN()-(COLUMN($AK14)-1),1) | AL14: =MID($P14,COLUMN()-(COLUMN($AK14)-1),1) | AM14: =MID($P14,COLUMN()-(COLUMN($AK14)-1),1) | AN14: =MID($P14,COLUMN()-(COLUMN($AK14)-1),1) | AO14: =MID($Q14,COLUMN()-(COLUMN($AO14)-1),1) | AP14: =MID($Q14,COLUMN()-(COLUMN($AO14)-1),1) | AQ14: =MID($Q14,COLUMN()-(COLUMN($AO14)-1),1) | AR14: =MID($Q14,COLUMN()-(COLUMN($AO14)-1),1) | AS14: =MID($R14,COLUMN()-(COLUMN($AS14)-1),1) | AT14: =MID($R14,COLUMN()-(COLUMN($AS14)-1),1) | AU14: =MID($R14,COLUMN()-(COLUMN($AS14)-1),1) | AV14: =MID($R14,COLUMN()-(COLUMN($AS14)-1),1) | AW14: =MID($S14,COLUMN()-(COLUMN($AW14)-1),1) | AX14: =MID($S14,COLUMN()-(COLUMN($AW14)-1),1) | AY14: =MID($S14,COLUMN()-(COLUMN($AW14)-1),1) | AZ14: =MID($S14,COLUMN()-(COLUMN($AW14)-1),1) | BA14: =MID($T14,COLUMN()-(COLUMN($BA14)-1),1) | BB14: =MID($T14,COLUMN()-(COLUMN($BA14)-1),1) | BC14: =MID($T14,COLUMN()-(COLUMN($BA14)-1),1) | BD14: =MID($T14,COLUMN()-(COLUMN($BA14)-1),1)
D15: 111 | E15: 80000292 | M15: =HEX2BIN(MID($E15,COLUMN()-(COLUMN($M15)-1),1),4) | N15: =HEX2BIN(MID($E15,COLUMN()-(COLUMN($M15)-1),1),4) | O15: =HEX2BIN(MID($E15,COLUMN()-(COLUMN($M15)-1),1),4) | P15: =HEX2BIN(MID($E15,COLUMN()-(COLUMN($M15)-1),1),4) | Q15: =HEX2BIN(MID($E15,COLUMN()-(COLUMN($M15)-1),1),4) | R15: =HEX2BIN(MID($E15,COLUMN()-(COLUMN($M15)-1),1),4) | S15: =HEX2BIN(MID($E15,COLUMN()-(COLUMN($M15)-1),1),4) | T15: =HEX2BIN(MID($E15,COLUMN()-(COLUMN($M15)-1),1),4) | Y15: =MID($M15,COLUMN()-(COLUMN($Y15)-1),1) | Z15: =MID($M15,COLUMN()-(COLUMN($Y15)-1),1) | AA15: =MID($M15,COLUMN()-(COLUMN($Y15)-1),1) | AB15: =MID($M15,COLUMN()-(COLUMN($Y15)-1),1) | AC15: =MID($N15,COLUMN()-(COLUMN($AC15)-1),1) | AD15: =MID($N15,COLUMN()-(COLUMN($AC15)-1),1) | AE15: =MID($N15,COLUMN()-(COLUMN($AC15)-1),1) | AF15: =MID($N15,COLUMN()-(COLUMN($AC15)-1),1) | AG15: =MID($O15,COLUMN()-(COLUMN($AG15)-1),1) | AH15: =MID($O15,COLUMN()-(COLUMN($AG15)-1),1) | AI15: =MID($O15,COLUMN()-(COLUMN($AG15)-1),1) | AJ15: =MID($O15,COLUMN()-(COLUMN($AG15)-1),1) | AK15: =MID($P15,COLUMN()-(COLUMN($AK15)-1),1) | AL15: =MID($P15,COLUMN()-(COLUMN($AK15)-1),1) | AM15: =MID($P15,COLUMN()-(COLUMN($AK15)-1),1) | AN15: =MID($P15,COLUMN()-(COLUMN($AK15)-1),1) | AO15: =MID($Q15,COLUMN()-(COLUMN($AO15)-1),1) | AP15: =MID($Q15,COLUMN()-(COLUMN($AO15)-1),1) | AQ15: =MID($Q15,COLUMN()-(COLUMN($AO15)-1),1) | AR15: =MID($Q15,COLUMN()-(COLUMN($AO15)-1),1) | AS15: =MID($R15,COLUMN()-(COLUMN($AS15)-1),1) | AT15: =MID($R15,COLUMN()-(COLUMN($AS15)-1),1) | AU15: =MID($R15,COLUMN()-(COLUMN($AS15)-1),1) | AV15: =MID($R15,COLUMN()-(COLUMN($AS15)-1),1) | AW15: =MID($S15,COLUMN()-(COLUMN($AW15)-1),1) | AX15: =MID($S15,COLUMN()-(COLUMN($AW15)-1),1) | AY15: =MID($S15,COLUMN()-(COLUMN($AW15)-1),1) | AZ15: =MID($S15,COLUMN()-(COLUMN($AW15)-1),1) | BA15: =MID($T15,COLUMN()-(COLUMN($BA15)-1),1) | BB15: =MID($T15,COLUMN()-(COLUMN($BA15)-1),1) | BC15: =MID($T15,COLUMN()-(COLUMN($BA15)-1),1) | BD15: =MID($T15,COLUMN()-(COLUMN($BA15)-1),1)
D16: 144 | E16: 86000226 | M16: =HEX2BIN(MID($E16,COLUMN()-(COLUMN($M16)-1),1),4) | N16: =HEX2BIN(MID($E16,COLUMN()-(COLUMN($M16)-1),1),4) | O16: =HEX2BIN(MID($E16,COLUMN()-(COLUMN($M16)-1),1),4) | P16: =HEX2BIN(MID($E16,COLUMN()-(COLUMN($M16)-1),1),4) | Q16: =HEX2BIN(MID($E16,COLUMN()-(COLUMN($M16)-1),1),4) | R16: =HEX2BIN(MID($E16,COLUMN()-(COLUMN($M16)-1),1),4) | S16: =HEX2BIN(MID($E16,COLUMN()-(COLUMN($M16)-1),1),4) | T16: =HEX2BIN(MID($E16,COLUMN()-(COLUMN($M16)-1),1),4) | Y16: =MID($M16,COLUMN()-(COLUMN($Y16)-1),1) | Z16: =MID($M16,COLUMN()-(COLUMN($Y16)-1),1) | AA16: =MID($M16,COLUMN()-(COLUMN($Y16)-1),1) | AB16: =MID($M16,COLUMN()-(COLUMN($Y16)-1),1) | AC16: =MID($N16,COLUMN()-(COLUMN($AC16)-1),1) | AD16: =MID($N16,COLUMN()-(COLUMN($AC16)-1),1) | AE16: =MID($N16,COLUMN()-(COLUMN($AC16)-1),1) | AF16: =MID($N16,COLUMN()-(COLUMN($AC16)-1),1) | AG16: =MID($O16,COLUMN()-(COLUMN($AG16)-1),1) | AH16: =MID($O16,COLUMN()-(COLUMN($AG16)-1),1) | AI16: =MID($O16,COLUMN()-(COLUMN($AG16)-1),1) | AJ16: =MID($O16,COLUMN()-(COLUMN($AG16)-1),1) | AK16: =MID($P16,COLUMN()-(COLUMN($AK16)-1),1) | AL16: =MID($P16,COLUMN()-(COLUMN($AK16)-1),1) | AM16: =MID($P16,COLUMN()-(COLUMN($AK16)-1),1) | AN16: =MID($P16,COLUMN()-(COLUMN($AK16)-1),1) | AO16: =MID($Q16,COLUMN()-(COLUMN($AO16)-1),1) | AP16: =MID($Q16,COLUMN()-(COLUMN($AO16)-1),1) | AQ16: =MID($Q16,COLUMN()-(COLUMN($AO16)-1),1) | AR16: =MID($Q16,COLUMN()-(COLUMN($AO16)-1),1) | AS16: =MID($R16,COLUMN()-(COLUMN($AS16)-1),1) | AT16: =MID($R16,COLUMN()-(COLUMN($AS16)-1),1) | AU16: =MID($R16,COLUMN()-(COLUMN($AS16)-1),1) | AV16: =MID($R16,COLUMN()-(COLUMN($AS16)-1),1) | AW16: =MID($S16,COLUMN()-(COLUMN($AW16)-1),1) | AX16: =MID($S16,COLUMN()-(COLUMN($AW16)-1),1) | AY16: =MID($S16,COLUMN()-(COLUMN($AW16)-1),1) | AZ16: =MID($S16,COLUMN()-(COLUMN($AW16)-1),1) | BA16: =MID($T16,COLUMN()-(COLUMN($BA16)-1),1) | BB16: =MID($T16,COLUMN()-(COLUMN($BA16)-1),1) | BC16: =MID($T16,COLUMN()-(COLUMN($BA16)-1),1) | BD16: =MID($T16,COLUMN()-(COLUMN($BA16)-1),1)
D17: 150 | E17: 80000216 | M17: =HEX2BIN(MID($E17,COLUMN()-(COLUMN($M17)-1),1),4) | N17: =HEX2BIN(MID($E17,COLUMN()-(COLUMN($M17)-1),1),4) | O17: =HEX2BIN(MID($E17,COLUMN()-(COLUMN($M17)-1),1),4) | P17: =HEX2BIN(MID($E17,COLUMN()-(COLUMN($M17)-1),1),4) | Q17: =HEX2BIN(MID($E17,COLUMN()-(COLUMN($M17)-1),1),4) | R17: =HEX2BIN(MID($E17,COLUMN()-(COLUMN($M17)-1),1),4) | S17: =HEX2BIN(MID($E17,COLUMN()-(COLUMN($M17)-1),1),4) | T17: =HEX2BIN(MID($E17,COLUMN()-(COLUMN($M17)-1),1),4) | Y17: =MID($M17,COLUMN()-(COLUMN($Y17)-1),1) | Z17: =MID($M17,COLUMN()-(COLUMN($Y17)-1),1) | AA17: =MID($M17,COLUMN()-(COLUMN($Y17)-1),1) | AB17: =MID($M17,COLUMN()-(COLUMN($Y17)-1),1) | AC17: =MID($N17,COLUMN()-(COLUMN($AC17)-1),1) | AD17: =MID($N17,COLUMN()-(COLUMN($AC17)-1),1) | AE17: =MID($N17,COLUMN()-(COLUMN($AC17)-1),1) | AF17: =MID($N17,COLUMN()-(COLUMN($AC17)-1),1) | AG17: =MID($O17,COLUMN()-(COLUMN($AG17)-1),1) | AH17: =MID($O17,COLUMN()-(COLUMN($AG17)-1),1) | AI17: =MID($O17,COLUMN()-(COLUMN($AG17)-1),1) | AJ17: =MID($O17,COLUMN()-(COLUMN($AG17)-1),1) | AK17: =MID($P17,COLUMN()-(COLUMN($AK17)-1),1) | AL17: =MID($P17,COLUMN()-(COLUMN($AK17)-1),1) | AM17: =MID($P17,COLUMN()-(COLUMN($AK17)-1),1) | AN17: =MID($P17,COLUMN()-(COLUMN($AK17)-1),1) | AO17: =MID($Q17,COLUMN()-(COLUMN($AO17)-1),1) | AP17: =MID($Q17,COLUMN()-(COLUMN($AO17)-1),1) | AQ17: =MID($Q17,COLUMN()-(COLUMN($AO17)-1),1) | AR17: =MID($Q17,COLUMN()-(COLUMN($AO17)-1),1) | AS17: =MID($R17,COLUMN()-(COLUMN($AS17)-1),1) | AT17: =MID($R17,COLUMN()-(COLUMN($AS17)-1),1) | AU17: =MID($R17,COLUMN()-(COLUMN($AS17)-1),1) | AV17: =MID($R17,COLUMN()-(COLUMN($AS17)-1),1) | AW17: =MID($S17,COLUMN()-(COLUMN($AW17)-1),1) | AX17: =MID($S17,COLUMN()-(COLUMN($AW17)-1),1) | AY17: =MID($S17,COLUMN()-(COLUMN($AW17)-1),1) | AZ17: =MID($S17,COLUMN()-(COLUMN($AW17)-1),1) | BA17: =MID($T17,COLUMN()-(COLUMN($BA17)-1),1) | BB17: =MID($T17,COLUMN()-(COLUMN($BA17)-1),1) | BC17: =MID($T17,COLUMN()-(COLUMN($BA17)-1),1) | BD17: =MID($T17,COLUMN()-(COLUMN($BA17)-1),1)
D18: 151 | E18: 801A0296 | M18: =HEX2BIN(MID($E18,COLUMN()-(COLUMN($M18)-1),1),4) | N18: =HEX2BIN(MID($E18,COLUMN()-(COLUMN($M18)-1),1),4) | O18: =HEX2BIN(MID($E18,COLUMN()-(COLUMN($M18)-1),1),4) | P18: =HEX2BIN(MID($E18,COLUMN()-(COLUMN($M18)-1),1),4) | Q18: =HEX2BIN(MID($E18,COLUMN()-(COLUMN($M18)-1),1),4) | R18: =HEX2BIN(MID($E18,COLUMN()-(COLUMN($M18)-1),1),4) | S18: =HEX2BIN(MID($E18,COLUMN()-(COLUMN($M18)-1),1),4) | T18: =HEX2BIN(MID($E18,COLUMN()-(COLUMN($M18)-1),1),4) | Y18: =MID($M18,COLUMN()-(COLUMN($Y18)-1),1) | Z18: =MID($M18,COLUMN()-(COLUMN($Y18)-1),1) | AA18: =MID($M18,COLUMN()-(COLUMN($Y18)-1),1) | AB18: =MID($M18,COLUMN()-(COLUMN($Y18)-1),1) | AC18: =MID($N18,COLUMN()-(COLUMN($AC18)-1),1) | AD18: =MID($N18,COLUMN()-(COLUMN($AC18)-1),1) | AE18: =MID($N18,COLUMN()-(COLUMN($AC18)-1),1) | AF18: =MID($N18,COLUMN()-(COLUMN($AC18)-1),1) | AG18: =MID($O18,COLUMN()-(COLUMN($AG18)-1),1) | AH18: =MID($O18,COLUMN()-(COLUMN($AG18)-1),1) | AI18: =MID($O18,COLUMN()-(COLUMN($AG18)-1),1) | AJ18: =MID($O18,COLUMN()-(COLUMN($AG18)-1),1) | AK18: =MID($P18,COLUMN()-(COLUMN($AK18)-1),1) | AL18: =MID($P18,COLUMN()-(COLUMN($AK18)-1),1) | AM18: =MID($P18,COLUMN()-(COLUMN($AK18)-1),1) | AN18: =MID($P18,COLUMN()-(COLUMN($AK18)-1),1) | AO18: =MID($Q18,COLUMN()-(COLUMN($AO18)-1),1) | AP18: =MID($Q18,COLUMN()-(COLUMN($AO18)-1),1) | AQ18: =MID($Q18,COLUMN()-(COLUMN($AO18)-1),1) | AR18: =MID($Q18,COLUMN()-(COLUMN($AO18)-1),1) | AS18: =MID($R18,COLUMN()-(COLUMN($AS18)-1),1) | AT18: =MID($R18,COLUMN()-(COLUMN($AS18)-1),1) | AU18: =MID($R18,COLUMN()-(COLUMN($AS18)-1),1) | AV18: =MID($R18,COLUMN()-(COLUMN($AS18)-1),1) | AW18: =MID($S18,COLUMN()-(COLUMN($AW18)-1),1) | AX18: =MID($S18,COLUMN()-(COLUMN($AW18)-1),1) | AY18: =MID($S18,COLUMN()-(COLUMN($AW18)-1),1) | AZ18: =MID($S18,COLUMN()-(COLUMN($AW18)-1),1) | BA18: =MID($T18,COLUMN()-(COLUMN($BA18)-1),1) | BB18: =MID($T18,COLUMN()-(COLUMN($BA18)-1),1) | BC18: =MID($T18,COLUMN()-(COLUMN($BA18)-1),1) | BD18: =MID($T18,COLUMN()-(COLUMN($BA18)-1),1)
D19: 153 | E19: 800002D6 | M19: =HEX2BIN(MID($E19,COLUMN()-(COLUMN($M19)-1),1),4) | N19: =HEX2BIN(MID($E19,COLUMN()-(COLUMN($M19)-1),1),4) | O19: =HEX2BIN(MID($E19,COLUMN()-(COLUMN($M19)-1),1),4) | P19: =HEX2BIN(MID($E19,COLUMN()-(COLUMN($M19)-1),1),4) | Q19: =HEX2BIN(MID($E19,COLUMN()-(COLUMN($M19)-1),1),4) | R19: =HEX2BIN(MID($E19,COLUMN()-(COLUMN($M19)-1),1),4) | S19: =HEX2BIN(MID($E19,COLUMN()-(COLUMN($M19)-1),1),4) | T19: =HEX2BIN(MID($E19,COLUMN()-(COLUMN($M19)-1),1),4) | Y19: =MID($M19,COLUMN()-(COLUMN($Y19)-1),1) | Z19: =MID($M19,COLUMN()-(COLUMN($Y19)-1),1) | AA19: =MID($M19,COLUMN()-(COLUMN($Y19)-1),1) | AB19: =MID($M19,COLUMN()-(COLUMN($Y19)-1),1) | AC19: =MID($N19,COLUMN()-(COLUMN($AC19)-1),1) | AD19: =MID($N19,COLUMN()-(COLUMN($AC19)-1),1) | AE19: =MID($N19,COLUMN()-(COLUMN($AC19)-1),1) | AF19: =MID($N19,COLUMN()-(COLUMN($AC19)-1),1) | AG19: =MID($O19,COLUMN()-(COLUMN($AG19)-1),1) | AH19: =MID($O19,COLUMN()-(COLUMN($AG19)-1),1) | AI19: =MID($O19,COLUMN()-(COLUMN($AG19)-1),1) | AJ19: =MID($O19,COLUMN()-(COLUMN($AG19)-1),1) | AK19: =MID($P19,COLUMN()-(COLUMN($AK19)-1),1) | AL19: =MID($P19,COLUMN()-(COLUMN($AK19)-1),1) | AM19: =MID($P19,COLUMN()-(COLUMN($AK19)-1),1) | AN19: =MID($P19,COLUMN()-(COLUMN($AK19)-1),1) | AO19: =MID($Q19,COLUMN()-(COLUMN($AO19)-1),1) | AP19: =MID($Q19,COLUMN()-(COLUMN($AO19)-1),1) | AQ19: =MID($Q19,COLUMN()-(COLUMN($AO19)-1),1) | AR19: =MID($Q19,COLUMN()-(COLUMN($AO19)-1),1) | AS19: =MID($R19,COLUMN()-(COLUMN($AS19)-1),1) | AT19: =MID($R19,COLUMN()-(COLUMN($AS19)-1),1) | AU19: =MID($R19,COLUMN()-(COLUMN($AS19)-1),1) | AV19: =MID($R19,COLUMN()-(COLUMN($AS19)-1),1) | AW19: =MID($S19,COLUMN()-(COLUMN($AW19)-1),1) | AX19: =MID($S19,COLUMN()-(COLUMN($AW19)-1),1) | AY19: =MID($S19,COLUMN()-(COLUMN($AW19)-1),1) | AZ19: =MID($S19,COLUMN()-(COLUMN($AW19)-1),1) | BA19: =MID($T19,COLUMN()-(COLUMN($BA19)-1),1) | BB19: =MID($T19,COLUMN()-(COLUMN($BA19)-1),1) | BC19: =MID($T19,COLUMN()-(COLUMN($BA19)-1),1) | BD19: =MID($T19,COLUMN()-(COLUMN($BA19)-1),1)
D20: 163 | E20: 800002CE | M20: =HEX2BIN(MID($E20,COLUMN()-(COLUMN($M20)-1),1),4) | N20: =HEX2BIN(MID($E20,COLUMN()-(COLUMN($M20)-1),1),4) | O20: =HEX2BIN(MID($E20,COLUMN()-(COLUMN($M20)-1),1),4) | P20: =HEX2BIN(MID($E20,COLUMN()-(COLUMN($M20)-1),1),4) | Q20: =HEX2BIN(MID($E20,COLUMN()-(COLUMN($M20)-1),1),4) | R20: =HEX2BIN(MID($E20,COLUMN()-(COLUMN($M20)-1),1),4) | S20: =HEX2BIN(MID($E20,COLUMN()-(COLUMN($M20)-1),1),4) | T20: =HEX2BIN(MID($E20,COLUMN()-(COLUMN($M20)-1),1),4) | Y20: =MID($M20,COLUMN()-(COLUMN($Y20)-1),1) | Z20: =MID($M20,COLUMN()-(COLUMN($Y20)-1),1) | AA20: =MID($M20,COLUMN()-(COLUMN($Y20)-1),1) | AB20: =MID($M20,COLUMN()-(COLUMN($Y20)-1),1) | AC20: =MID($N20,COLUMN()-(COLUMN($AC20)-1),1) | AD20: =MID($N20,COLUMN()-(COLUMN($AC20)-1),1) | AE20: =MID($N20,COLUMN()-(COLUMN($AC20)-1),1) | AF20: =MID($N20,COLUMN()-(COLUMN($AC20)-1),1) | AG20: =MID($O20,COLUMN()-(COLUMN($AG20)-1),1) | AH20: =MID($O20,COLUMN()-(COLUMN($AG20)-1),1) | AI20: =MID($O20,COLUMN()-(COLUMN($AG20)-1),1) | AJ20: =MID($O20,COLUMN()-(COLUMN($AG20)-1),1) | AK20: =MID($P20,COLUMN()-(COLUMN($AK20)-1),1) | AL20: =MID($P20,COLUMN()-(COLUMN($AK20)-1),1) | AM20: =MID($P20,COLUMN()-(COLUMN($AK20)-1),1) | AN20: =MID($P20,COLUMN()-(COLUMN($AK20)-1),1) | AO20: =MID($Q20,COLUMN()-(COLUMN($AO20)-1),1) | AP20: =MID($Q20,COLUMN()-(COLUMN($AO20)-1),1) | AQ20: =MID($Q20,COLUMN()-(COLUMN($AO20)-1),1) | AR20: =MID($Q20,COLUMN()-(COLUMN($AO20)-1),1) | AS20: =MID($R20,COLUMN()-(COLUMN($AS20)-1),1) | AT20: =MID($R20,COLUMN()-(COLUMN($AS20)-1),1) | AU20: =MID($R20,COLUMN()-(COLUMN($AS20)-1),1) | AV20: =MID($R20,COLUMN()-(COLUMN($AS20)-1),1) | AW20: =MID($S20,COLUMN()-(COLUMN($AW20)-1),1) | AX20: =MID($S20,COLUMN()-(COLUMN($AW20)-1),1) | AY20: =MID($S20,COLUMN()-(COLUMN($AW20)-1),1) | AZ20: =MID($S20,COLUMN()-(COLUMN($AW20)-1),1) | BA20: =MID($T20,COLUMN()-(COLUMN($BA20)-1),1) | BB20: =MID($T20,COLUMN()-(COLUMN($BA20)-1),1) | BC20: =MID($T20,COLUMN()-(COLUMN($BA20)-1),1) | BD20: =MID($T20,COLUMN()-(COLUMN($BA20)-1),1)
D21: 277 | E21: 400001FD | M21: =HEX2BIN(MID($E21,COLUMN()-(COLUMN($M21)-1),1),4) | N21: =HEX2BIN(MID($E21,COLUMN()-(COLUMN($M21)-1),1),4) | O21: =HEX2BIN(MID($E21,COLUMN()-(COLUMN($M21)-1),1),4) | P21: =HEX2BIN(MID($E21,COLUMN()-(COLUMN($M21)-1),1),4) | Q21: =HEX2BIN(MID($E21,COLUMN()-(COLUMN($M21)-1),1),4) | R21: =HEX2BIN(MID($E21,COLUMN()-(COLUMN($M21)-1),1),4) | S21: =HEX2BIN(MID($E21,COLUMN()-(COLUMN($M21)-1),1),4) | T21: =HEX2BIN(MID($E21,COLUMN()-(COLUMN($M21)-1),1),4) | Y21: =MID($M21,COLUMN()-(COLUMN($Y21)-1),1) | Z21: =MID($M21,COLUMN()-(COLUMN($Y21)-1),1) | AA21: =MID($M21,COLUMN()-(COLUMN($Y21)-1),1) | AB21: =MID($M21,COLUMN()-(COLUMN($Y21)-1),1) | AC21: =MID($N21,COLUMN()-(COLUMN($AC21)-1),1) | AD21: =MID($N21,COLUMN()-(COLUMN($AC21)-1),1) | AE21: =MID($N21,COLUMN()-(COLUMN($AC21)-1),1) | AF21: =MID($N21,COLUMN()-(COLUMN($AC21)-1),1) | AG21: =MID($O21,COLUMN()-(COLUMN($AG21)-1),1) | AH21: =MID($O21,COLUMN()-(COLUMN($AG21)-1),1) | AI21: =MID($O21,COLUMN()-(COLUMN($AG21)-1),1) | AJ21: =MID($O21,COLUMN()-(COLUMN($AG21)-1),1) | AK21: =MID($P21,COLUMN()-(COLUMN($AK21)-1),1) | AL21: =MID($P21,COLUMN()-(COLUMN($AK21)-1),1) | AM21: =MID($P21,COLUMN()-(COLUMN($AK21)-1),1) | AN21: =MID($P21,COLUMN()-(COLUMN($AK21)-1),1) | AO21: =MID($Q21,COLUMN()-(COLUMN($AO21)-1),1) | AP21: =MID($Q21,COLUMN()-(COLUMN($AO21)-1),1) | AQ21: =MID($Q21,COLUMN()-(COLUMN($AO21)-1),1) | AR21: =MID($Q21,COLUMN()-(COLUMN($AO21)-1),1) | AS21: =MID($R21,COLUMN()-(COLUMN($AS21)-1),1) | AT21: =MID($R21,COLUMN()-(COLUMN($AS21)-1),1) | AU21: =MID($R21,COLUMN()-(COLUMN($AS21)-1),1) | AV21: =MID($R21,COLUMN()-(COLUMN($AS21)-1),1) | AW21: =MID($S21,COLUMN()-(COLUMN($AW21)-1),1) | AX21: =MID($S21,COLUMN()-(COLUMN($AW21)-1),1) | AY21: =MID($S21,COLUMN()-(COLUMN($AW21)-1),1) | AZ21: =MID($S21,COLUMN()-(COLUMN($AW21)-1),1) | BA21: =MID($T21,COLUMN()-(COLUMN($BA21)-1),1) | BB21: =MID($T21,COLUMN()-(COLUMN($BA21)-1),1) | BC21: =MID($T21,COLUMN()-(COLUMN($BA21)-1),1) | BD21: =MID($T21,COLUMN()-(COLUMN($BA21)-1),1)
